Workbook

Sheet Geração_Dezembro
A1: Mês | B1: UC | C1: Usina BC | D1: SPE | E1: Projeto | F1: Geração Plataforma MWh | G1: Geração Local MWh | H1: Previsão | I1: Atingimento %
A2: 12 | B2: 10031214850 | C2: UFV Araçu I | D2: BC Energia Araçu I.I | E2: BC Araçu I | G2: =(18301.5+18559+18704.1+18474.3+17544.2+16254.4+18781.5)/1000 -> 126.619 | H2: 135.1 | I2: =IF(G2<>0,G2/H2,F2/H2) -> 0.93722428
A3: 12 | B3: 10031394475 | C3: UFV Araçu II | D3: BC Energia Araçu II.II | E3: BC Araçu II | F3: 42.58 | H3: 36.62 | I3: =IF(G3<>0,G3/H3,F3/H3) -> 1.1627526
A4: 12 | B4: 10031394572 | C4: UFV Araçu III | D4: BC Energia Araçu II.III | E4: BC Araçu II | F4: 38.21 | H4: 43.16 | I4: =IF(G4<>0,G4/H4,F4/H4) -> 0.88531047
A5: 12 | B5: 10031394211 | C5: UFV Araçu IV | D5: BC Energia Araçu II.IV | E5: BC Araçu II | F5: 52.18 | H5: 78.33 | I5: =IF(G5<>0,G5/H5,F5/H5) -> 0.66615601
A6: 12 | B6: 10031394599 | C6: UFV Araçu V | D6: BC Energia Araçu II.V | E6: BC Araçu II | F6: 77.08 | H6: 87.5 | I6: =IF(G6<>0,G6/H6,F6/H6) -> 0.88091429
A7: 12 | B7: 10035044444 | C7: UFV Araçu VI | D7: BC Energia Araçu III.VI | E7: BC Araçu III | F7: 19.14 | H7: 20.47 | I7: =IF(G7<>0,G7/H7,F7/H7) -> 0.93502687
A8: 12 | B8: 10035044363 | C8: UFV Araçu VII | D8: BC Energia Araçu III.VII | E8: BC Araçu III | F8: 18.75 | H8: 20.35 | I8: =IF(G8<>0,G8/H8,F8/H8) -> 0.92137592
A9: 12 | B9: 10035302079 | C9: UFV Araçu VIII | D9: BC Energia Araçu IV.VIII | E9: BC Araçu IV | F9: 45.71 | H9: 53.49 | I9: =IF(G9<>0,G9/H9,F9/H9) -> 0.85455225
A10: 12 | B10: 6/4136603-0 | C10: UFV Barra do Garças I | D10: BC Energia Barra das Garças I | E10: BC Barra do Garças | F10: 12.03 | H10: 11.94 | I10: =IF(G10<>0,G10/H10,F10/H10) -> 1.0075377
A11: 12 | B11: 6/4136542-0 | C11: UFV Barra do Garças II | D11: BC Energia Barra das Garças II | E11: BC Barra do Garças | F11: 45.57 | H11: 45.27 | I11: =IF(G11<>0,G11/H11,F11/H11) -> 1.0066269
A12: 12 | B12: 6/4136538-8 | C12: UFV Barra do Garças III | D12: BC Energia Barra das Garças III | E12: BC Barra do Garças | F12: 45.36 | H12: 46.02 | I12: =IF(G12<>0,G12/H12,F12/H12) -> 0.98565841
A13: 12 | B13: 10031246905 | C13: UFV Bom Sucesso | D13: BC Energia Bom Sucesso I | E13: BC Bom Sucesso | F13: 95.25 | G13: 96.64 | H13: 100.8 | I13: =IF(G13<>0,G13/H13,F13/H13) -> 0.95873016
A14: 12 | B14: 10035461975 | C14: UFV Caiapônia I | D14: BC Energia Caiapônia I.I | E14: BC Caiapônia I | F14: 81.63 | H14: 91.2 | I14: =IF(G14<>0,G14/H14,F14/H14) -> 0.89506579
A15: 12 | B15: 10035461983 | C15: UFV Caiapônia II | D15: BC Energia Caiapônia I.II | E15: BC Caiapônia I | F15: 68.91 | H15: 77.81 | I15: =IF(G15<>0,G15/H15,F15/H15) -> 0.88561882
A16: 12 | B16: 10035505336 | C16: UFV Caiapônia III | D16: BC Energia Caiapônia I.III | E16: BC Caiapônia I | F16: 51.45 | H16: 56.31 | I16: =IF(G16<>0,G16/H16,F16/H16) -> 0.91369206
A17: 12 | B17: 10035462122 | C17: UFV Caiapônia IV | D17: BC Energia Caiapônia I.IV | E17: BC Caiapônia I | F17: 40.09 | H17: 42.99 | I17: =IF(G17<>0,G17/H17,F17/H17) -> 0.93254245
A18: 12 | B18: 10035462130 | C18: UFV Caiapônia V | D18: BC Energia Caiapônia I.V | E18: BC Caiapônia I | F18: 42.28 | H18: 48.32 | I18: =IF(G18<>0,G18/H18,F18/H18) -> 0.875
A19: 12 | B19: 10035462084 | C19: UFV Caiaponia VI | D19: BC Energia Caiapônia II.VI | E19: BC Caiapônia II | F19: 182.71 | H19: 232.78 | I19: =IF(G19<>0,G19/H19,F19/H19) -> 0.7849042
A20: 12 | B20: 10035462114 | C20: UFV Caiaponia VII | D20: BC Energia Caiapônia II.VII | E20: BC Caiapônia II | F20: 177.1 | H20: 222.66 | I20: =IF(G20<>0,G20/H20,F20/H20) -> 0.7953831
A21: 12 | B21: 10035462262 | C21: UFV Caiaponia VIII | D21: BC Energia Caiapônia II.VIII | E21: BC Caiapônia II | F21: 179.44 | H21: 230.76 | I21: =IF(G21<>0,G21/H21,F21/H21) -> 0.77760444
A22: 12 | B22: 10035977122 | C22: UFV Palmeiras de Goiás 1.1 | D22: BC Energia Camarão - Palmeiras de Goiais I.I | E22: BC Camarão I - Palmeiras de Goiás I | F22: 195.04 | H22: 252.1 | I22: =IF(G22<>0,G22/H22,F22/H22) -> 0.77366125
A23: 12 | B23: 10035977130 | C23: UFV Palmeiras de Goiás 1.2 | D23: BC Energia Camarão - Palmeiras de Goiais I.II | E23: BC Camarão I - Palmeiras de Goiás I | F23: 200.42 | H23: 251.3 | I23: =IF(G23<>0,G23/H23,F23/H23) -> 0.79753283
A24: 12 | B24: 10035977149 | C24: UFV Palmeiras de Goiás 1.3 | D24: BC Energia Camarão - Palmeiras de Goiais I.III | E24: BC Camarão I - Palmeiras de Goiás I | F24: 200.02 | H24: 251.2 | I24: =IF(G24<>0,G24/H24,F24/H24) -> 0.79625796
A25: 12 | B25: 10035977157 | C25: UFV Palmeiras de Goiás 1.4 | D25: BC Energia Camarão - Palmeiras de Goiais I.IV | E25: BC Camarão I - Palmeiras de Goiás I | F25: 200.34 | H25: 250.8 | I25: =IF(G25<>0,G25/H25,F25/H25) -> 0.79880383
... A41: 12 | B41: 10035156609 | C41: UFV Panamá VII | D41: BC Energia Panamá I.VII | E41: BC Panamá I | F41: 9.64 | H41: 9.25 | I41: =IF(G41<>0,G41/H41,F41/H41) -> 1.0421622
A42: 12 | B42: 2353016-2 | C42: UFV Paranoá I | D42: BC Energia Paranoá I.I | E42: BC Paranoá I | F42: 85.92 | H42: 88.8 | I42: =IF(G42<>0,G42/H42,F42/H42) -> 0.96756757
A43: 12 | B43: 2352648-3 | C43: UFV Paranoá II | D43: BC Energia Paranoá I.II | E43: BC Paranoá I | F43: 45 | H43: 48.92 | I43: =IF(G43<>0,G43/H43,F43/H43) -> 0.91986917
A44: 12 | B44: 2353023-5 | C44: UFV Paranoá III | D44: BC Energia Paranoá I.III | E44: BC Paranoá I | F44: 19.02 | H44: 53.63 | I44: =IF(G44<>0,G44/H44,F44/H44) -> 0.35465225
A45: 12 | B45: 2346023-7 | C45: UFV Paranoá IV | D45: BC Energia Paranoá I.IV | E45: BC Paranoá I | F45: 59.93 | H45: 61.45 | I45: =IF(G45<>0,G45/H45,F45/H45) -> 0.97526444
A46: 12 | B46: 2346009-1 | C46: UFV Paranoá V | D46: BC Energia Paranoá I.V | E46: BC Paranoá I | F46: 26.65 | H46: 27.47 | I46: =IF(G46<>0,G46/H46,F46/H46) -> 0.97014925
A47: 12 | B47: 2345997-2 | C47: UFV Paranoá VI | D47: BC Energia Paranoá I.VI | E47: BC Paranoá I | F47: 27.12 | H47: 27.47 | I47: =IF(G47<>0,G47/H47,F47/H47) -> 0.98725883
A48: 12 | B48: 2345992-1 | C48: UFV Paranoá VII | D48: BC Energia Paranoá I.VII | E48: BC Paranoá I | F48: 32.6 | H48: 62.33 | I48: =IF(G48<>0,G48/H48,F48/H48) -> 0.52302262
A49: 12 | B49: 2352661-0 | C49: UFV Paranoá VIII | D49: BC Energia Paranoá I.VIII | E49: BC Paranoá I | F49: 28.34 | H49: 29.29 | I49: =IF(G49<>0,G49/H49,F49/H49) -> 0.96756572
A50: 12 | B50: 10029355760 | C50: UFV Rio Bonito 1 | D50: BC Energia Rio Bonito I.I | E50: BC Rio Bonito I | F50: 160.13 | H50: 159.8 | I50: =IF(G50<>0,G50/H50,F50/H50) -> 1.0020651
A51: 12 | B51: 10035716108 | C51: UFV Rio Bonito 2 | D51: BC Energia Rio Bonito II.II | E51: BC Rio Bonito II | F51: 50.52 | H51: 54.99 | I51: =IF(G51<>0,G51/H51,F51/H51) -> 0.91871249
A52: 12 | B52: 10029848863 | C52: UFV Rio Monte I | D52: BC Energia Rio Monte I.I | E52: BC Rio Monte I | F52: 11.87 | H52: 13.69 | I52: =IF(G52<>0,G52/H52,F52/H52) -> 0.86705625
A53: 12 | B53: 10029848855 | C53: UFV Rio Monte II | D53: BC Energia Rio Monte I.II | E53: BC Rio Monte I | F53: 51.68 | H53: 55.75 | I53: =IF(G53<>0,G53/H53,F53/H53) -> 0.92699552
A54: 12 | B54: 10029848820 | C54: UFV Rio Monte III | D54: BC Energia Rio Monte I.III | E54: BC Rio Monte I | F54: 90.84 | H54: 102.2 | I54: =IF(G54<>0,G54/H54,F54/H54) -> 0.8888454
A55: 12 | B55: 3014365852 | C55: UFV Varjão de Minas I | D55: BC Energia Varjão de Minas I.I | E55: BC Varjão de Minas I | F55: 202.31 | H55: 233.1 | I55: =IF(G55<>0,G55/H55,F55/H55) -> 0.86791077
...

Sheet Março 2026
A1: UC | B1: UFV | C1: Tag | D1: Início Real do Evento | E1: Início | F1: Fim | G1: Duração | H1: Estado Operativo | I1: Condição Operativa | J1: Origem | K1: Equipamento | L1: Causa | M1: Causas Padrão | N1: Resolução | O1: Observação | P1: Concat - duplicata | Q1: Combinação
B2: BC Aracu5.2 | C2: Inverter(MBUS-1) | D2: 46027.385 | E2: 46082 | F2: 46094.469 | G2: =+F2-E2 -> 12.46875 | H2: DEM | J2: TRF | K2: Transformador | L2: Inversor 1 apresentou falha. Ao realizar a análise em campo, verificou-se curto circuito em uma das fases do trafo. | M2: Falha Inversor | N2: Prestador de Serviço O&M | O2: Identificado no sistema desequilibrio de fase, ao fazer a inspeção o mantenedor identificou curto circuito no trafo, o mesmo fez as manobras e desenergizou a UFV. Transformador foi coletado e encaminhado para garantia. Após retorno de garantia, transformador foi instalado e comissionado novamente. A normalização da geração se deu em 16/03. | P2: =_xlfn.CONCAT(B2,C2,D2,E2,F2) -> BC Aracu5.2Inverter(MBUS-1)46027,38541666674608246094,46875 | Q2: =_xlfn.CONCAT(H2,I2,J2) -> DEMTRF
B3: BC Formoso2.1 | C3: Inverter(MBUS-12) | D3: 46082.153 | E3: 46082.153 | F3: 46083.34 | G3: =+F3-E3 -> 1.1875 | H3: DAU | J3: RDE | K3: =_xlfn.XLOOKUP(J3,REF!$D$2:$D$12,REF!$E$2:$E$12) -> Rede | L3: Queda de rede da concessionária. | M3: Falha Rede | N3: Distribuidora | O3: Devido a uma falha no nobreak, não foi possível a atuação do relé. Foi realizada uma inspeção visual, não sendo identificada nenhuma anomalia. Em seguida, foi efetuado o rearme da usina. | P3: =_xlfn.CONCAT(B3,C3,D3,E3,F3) -> BC Formoso2.1Inverter(MBUS-12)46082,152777777846082,152777777846083,3402777778 | Q3: =_xlfn.CONCAT(H3,I3,J3) -> DAURDE
B4: BC Formoso2.1 | C4: Inverter(MBUS-14) | D4: 46082.153 | E4: 46082.153 | F4: 46083.34 | G4: =+F4-E4 -> 1.1875 | H4: DAU | J4: RDE | K4: =_xlfn.XLOOKUP(J4,REF!$D$2:$D$12,REF!$E$2:$E$12) -> Rede | L4: Queda de rede da concessionária. | M4: Falha Rede | N4: Distribuidora | O4: Devido a uma falha no nobreak, não foi possível a atuação do relé. Foi realizada uma inspeção visual, não sendo identificada nenhuma anomalia. Em seguida, foi efetuado o rearme da usina. | P4: =_xlfn.CONCAT(B4,C4,D4,E4,F4) -> BC Formoso2.1Inverter(MBUS-14)46082,152777777846082,152777777846083,3402777778 | Q4: =_xlfn.CONCAT(H4,I4,J4) -> DAURDE
B5: BC Formoso2.1 | C5: Inverter(MBUS-13) | D5: 46082.153 | E5: 46082.153 | F5: 46083.34 | G5: =+F5-E5 -> 1.1875 | H5: DAU | J5: RDE | K5: =_xlfn.XLOOKUP(J5,REF!$D$2:$D$12,REF!$E$2:$E$12) -> Rede | L5: Queda de rede da concessionária. | M5: Falha Rede | N5: Distribuidora | O5: Devido a uma falha no nobreak, não foi possível a atuação do relé. Foi realizada uma inspeção visual, não sendo identificada nenhuma anomalia. Em seguida, foi efetuado o rearme da usina. | P5: =_xlfn.CONCAT(B5,C5,D5,E5,F5) -> BC Formoso2.1Inverter(MBUS-13)46082,152777777846082,152777777846083,3402777778 | Q5: =_xlfn.CONCAT(H5,I5,J5) -> DAURDE
B6: BC Formoso2.1 | C6: Inverter(MBUS-1) | D6: 46082.153 | E6: 46082.153 | F6: 46083.34 | G6: =+F6-E6 -> 1.1875 | H6: DAU | J6: RDE | K6: =_xlfn.XLOOKUP(J6,REF!$D$2:$D$12,REF!$E$2:$E$12) -> Rede | L6: Queda de rede da concessionária. | M6: Falha Rede | N6: Distribuidora | O6: Devido a uma falha no nobreak, não foi possível a atuação do relé. Foi realizada uma inspeção visual, não sendo identificada nenhuma anomalia. Em seguida, foi efetuado o rearme da usina. | P6: =_xlfn.CONCAT(B6,C6,D6,E6,F6) -> BC Formoso2.1Inverter(MBUS-1)46082,152777777846082,152777777846083,3402777778 | Q6: =_xlfn.CONCAT(H6,I6,J6) -> DAURDE
B7: BC Formoso2.2 | C7: Inverter(MBUS-14) | D7: 46082.306 | E7: 46082.306 | F7: 46084.342 | G7: =+F7-E7 -> 2.0361111 | H7: DAU | J7: RDE | K7: =_xlfn.XLOOKUP(J7,REF!$D$2:$D$12,REF!$E$2:$E$12) -> Rede | L7: Queda de rede da concessionária. | M7: Falha Rede | N7: Distribuidora | O7: Após a realização de uma inspeção visual, não foram identificadas anomalias no sistema. Em seguida, foi efetuado o reset do relé, restabelecendo a operação normal da usina. | P7: =_xlfn.CONCAT(B7,C7,D7,E7,F7) -> BC Formoso2.2Inverter(MBUS-14)46082,305555555646082,305555555646084,3416666667 | Q7: =_xlfn.CONCAT(H7,I7,J7) -> DAURDE
B8: BC Formoso2.2 | C8: Inverter(MBUS-13) | D8: 46082.306 | E8: 46082.306 | F8: 46084.342 | G8: =+F8-E8 -> 2.0361111 | H8: DAU | J8: RDE | K8: =_xlfn.XLOOKUP(J8,REF!$D$2:$D$12,REF!$E$2:$E$12) -> Rede | L8: Queda de rede da concessionária. | M8: Falha Rede | N8: Distribuidora | O8: Após a realização de uma inspeção visual, não foram identificadas anomalias no sistema. Em seguida, foi efetuado o reset do relé, restabelecendo a operação normal da usina. | P8: =_xlfn.CONCAT(B8,C8,D8,E8,F8) -> BC Formoso2.2Inverter(MBUS-13)46082,305555555646082,305555555646084,3416666667 | Q8: =_xlfn.CONCAT(H8,I8,J8) -> DAURDE
B9: BC Formoso2.2 | C9: Inverter(MBUS-12) | D9: 46082.306 | E9: 46082.306 | F9: 46084.342 | G9: =+F9-E9 -> 2.0361111 | H9: DAU | J9: RDE | K9: =_xlfn.XLOOKUP(J9,REF!$D$2:$D$12,REF!$E$2:$E$12) -> Rede | L9: Queda de rede da concessionária. | M9: Falha Rede | N9: Distribuidora | O9: Após a realização de uma inspeção visual, não foram identificadas anomalias no sistema. Em seguida, foi efetuado o reset do relé, restabelecendo a operação normal da usina. | P9: =_xlfn.CONCAT(B9,C9,D9,E9,F9) -> BC Formoso2.2Inverter(MBUS-12)46082,305555555646082,305555555646084,3416666667 | Q9: =_xlfn.CONCAT(H9,I9,J9) -> DAURDE
B10: BC Formoso2.2 | C10: Inverter(MBUS-1) | D10: 46082.306 | E10: 46082.306 | F10: 46084.342 | G10: =+F10-E10 -> 2.0361111 | H10: DAU | J10: RDE | K10: =_xlfn.XLOOKUP(J10,REF!$D$2:$D$12,REF!$E$2:$E$12) -> Rede | L10: Queda de rede da concessionária. | M10: Falha Rede | N10: Distribuidora | O10: Após a realização de uma inspeção visual, não foram identificadas anomalias no sistema. Em seguida, foi efetuado o reset do relé, restabelecendo a operação normal da usina. | P10: =_xlfn.CONCAT(B10,C10,D10,E10,F10) -> BC Formoso2.2Inverter(MBUS-1)46082,305555555646082,305555555646084,3416666667 | Q10: =_xlfn.CONCAT(H10,I10,J10) -> DAURDE
B11: BC Bom Sucesso | C11: SG60KTL | D11: 46082.968 | E11: 46082.968 | F11: 46083.351 | G11: =+F11-E11 -> 0.38263889 | H11: LIG | I11: RFO | J11: INT | K11: =_xlfn.XLOOKUP(J11,REF!$D$2:$D$12,REF!$E$2:$E$12) -> Internet | L11: Indisponibilidade de comunicação devido a problema no provedor de internet. | M11: Conexão c/ Internet | N11: Provedora de Internet | O11: Foi realizada inspeção visual no sistema, não sendo identificadas anomalias. Após a normalização do serviço de internet, a comunicação foi restabelecida e a usina voltou a operar normalmente. | P11: =_xlfn.CONCAT(B11,C11,D11,E11,F11) -> BC Bom SucessoSG60KTL46082,968055555646082,968055555646083,3506944444 | Q11: =_xlfn.CONCAT(H11,I11,J11) -> LIGRFOINT
B12: BC Bom Sucesso | C12: I | D12: 46082.968 | E12: 46082.968 | F12: 46083.351 | G12: =+F12-E12 -> 0.38263889 | H12: LIG | I12: RFO | J12: INT | K12: =_xlfn.XLOOKUP(J12,REF!$D$2:$D$12,REF!$E$2:$E$12) -> Internet | L12: Indisponibilidade de comunicação devido a problema no provedor de internet. | M12: Conexão c/ Internet | N12: Provedora de Internet | O12: Foi realizada inspeção visual no sistema, não sendo identificadas anomalias. Após a normalização do serviço de internet, a comunicação foi restabelecida e a usina voltou a operar normalmente. | P12: =_xlfn.CONCAT(B12,C12,D12,E12,F12) -> BC Bom SucessoI46082,968055555646082,968055555646083,3506944444 | Q12: =_xlfn.CONCAT(H12,I12,J12) -> LIGRFOINT
B13: BC Bom Sucesso | C13: G | D13: 46082.968 | E13: 46082.968 | F13: 46083.351 | G13: =+F13-E13 -> 0.38263889 | H13: LIG | I13: RFO | J13: INT | K13: =_xlfn.XLOOKUP(J13,REF!$D$2:$D$12,REF!$E$2:$E$12) -> Internet | L13: Indisponibilidade de comunicação devido a problema no provedor de internet. | M13: Conexão c/ Internet | N13: Provedora de Internet | O13: Foi realizada inspeção visual no sistema, não sendo identificadas anomalias. Após a normalização do serviço de internet, a comunicação foi restabelecida e a usina voltou a operar normalmente. | P13: =_xlfn.CONCAT(B13,C13,D13,E13,F13) -> BC Bom SucessoG46082,968055555646082,968055555646083,3506944444 | Q13: =_xlfn.CONCAT(H13,I13,J13) -> LIGRFOINT
B14: BC Bom Sucesso | C14: K | D14: 46082.968 | E14: 46082.968 | F14: 46083.351 | G14: =+F14-E14 -> 0.38263889 | H14: LIG | I14: RFO | J14: INT | K14: =_xlfn.XLOOKUP(J14,REF!$D$2:$D$12,REF!$E$2:$E$12) -> Internet | L14: Indisponibilidade de comunicação devido a problema no provedor de internet. | M14: Conexão c/ Internet | N14: Provedora de Internet | O14: Foi realizada inspeção visual no sistema, não sendo identificadas anomalias. Após a normalização do serviço de internet, a comunicação foi restabelecida e a usina voltou a operar normalmente. | P14: =_xlfn.CONCAT(B14,C14,D14,E14,F14) -> BC Bom SucessoK46082,968055555646082,968055555646083,3506944444 | Q14: =_xlfn.CONCAT(H14,I14,J14) -> LIGRFOINT
B15: BC Bom Sucesso | C15: H | D15: 46082.968 | E15: 46082.968 | F15: 46083.351 | G15: =+F15-E15 -> 0.38263889 | H15: LIG | I15: RFO | J15: INT | K15: =_xlfn.XLOOKUP(J15,REF!$D$2:$D$12,REF!$E$2:$E$12) -> Internet | L15: Indisponibilidade de comunicação devido a problema no provedor de internet. | M15: Conexão c/ Internet | N15: Provedora de Internet | O15: Foi realizada inspeção visual no sistema, não sendo identificadas anomalias. Após a normalização do serviço de internet, a comunicação foi restabelecida e a usina voltou a operar normalmente. | P15: =_xlfn.CONCAT(B15,C15,D15,E15,F15) -> BC Bom SucessoH46082,968055555646082,968055555646083,3506944444 | Q15: =_xlfn.CONCAT(H15,I15,J15) -> LIGRFOINT
B16: BC Bom Sucesso | C16: F | D16: 46082.968 | E16: 46082.968 | F16: 46083.351 | G16: =+F16-E16 -> 0.38263889 | H16: LIG | I16: RFO | J16: INT | K16: =_xlfn.XLOOKUP(J16,REF!$D$2:$D$12,REF!$E$2:$E$12) -> Internet | L16: Indisponibilidade de comunicação devido a problema no provedor de internet. | M16: Conexão c/ Internet | N16: Provedora de Internet | O16: Foi realizada inspeção visual no sistema, não sendo identificadas anomalias. Após a normalização do serviço de internet, a comunicação foi restabelecida e a usina voltou a operar normalmente. | P16: =_xlfn.CONCAT(B16,C16,D16,E16,F16) -> BC Bom SucessoF46082,968055555646082,968055555646083,3506944444 | Q16: =_xlfn.CONCAT(H16,I16,J16) -> LIGRFOINT
B17: BC Bom Sucesso | C17: D | D17: 46082.968 | E17: 46082.968 | F17: 46083.351 | G17: =+F17-E17 -> 0.38263889 | H17: LIG | I17: RFO | J17: INT | K17: =_xlfn.XLOOKUP(J17,REF!$D$2:$D$12,REF!$E$2:$E$12) -> Internet | L17: Indisponibilidade de comunicação devido a problema no provedor de internet. | M17: Conexão c/ Internet | N17: Provedora de Internet | O17: Foi realizada inspeção visual no sistema, não sendo identificadas anomalias. Após a normalização do serviço de internet, a comunicação foi restabelecida e a usina voltou a operar normalmente. | P17: =_xlfn.CONCAT(B17,C17,D17,E17,F17) -> BC Bom SucessoD46082,968055555646082,968055555646083,3506944444 | Q17: =_xlfn.CONCAT(H17,I17,J17) -> LIGRFOINT
B18: BC Bom Sucesso | C18: E | D18: 46082.968 | E18: 46082.968 | F18: 46083.351 | G18: =+F18-E18 -> 0.38263889 | H18: LIG | I18: RFO | J18: INT | K18: =_xlfn.XLOOKUP(J18,REF!$D$2:$D$12,REF!$E$2:$E$12) -> Internet | L18: Indisponibilidade de comunicação devido a problema no provedor de internet. | M18: Conexão c/ Internet | N18: Provedora de Internet | O18: Foi realizada inspeção visual no sistema, não sendo identificadas anomalias. Após a normalização do serviço de internet, a comunicação foi restabelecida e a usina voltou a operar normalmente. | P18: =_xlfn.CONCAT(B18,C18,D18,E18,F18) -> BC Bom SucessoE46082,968055555646082,968055555646083,3506944444 | Q18: =_xlfn.CONCAT(H18,I18,J18) -> LIGRFOINT
B19: BC Bom Sucesso | C19: C | D19: 46082.968 | E19: 46082.968 | F19: 46083.351 | G19: =+F19-E19 -> 0.38263889 | H19: LIG | I19: RFO | J19: INT | K19: =_xlfn.XLOOKUP(J19,REF!$D$2:$D$12,REF!$E$2:$E$12) -> Internet | L19: Indisponibilidade de comunicação devido a problema no provedor de internet. | M19: Conexão c/ Internet | N19: Provedora de Internet | O19: Foi realizada inspeção visual no sistema, não sendo identificadas anomalias. Após a normalização do serviço de internet, a comunicação foi restabelecida e a usina voltou a operar normalmente. | P19: =_xlfn.CONCAT(B19,C19,D19,E19,F19) -> BC Bom SucessoC46082,968055555646082,968055555646083,3506944444 | Q19: =_xlfn.CONCAT(H19,I19,J19) -> LIGRFOINT
B20: BC Bom Sucesso | C20: B | D20: 46082.968 | E20: 46082.968 | F20: 46083.351 | G20: =+F20-E20 -> 0.38263889 | H20: LIG | I20: RFO | J20: INT | K20: =_xlfn.XLOOKUP(J20,REF!$D$2:$D$12,REF!$E$2:$E$12) -> Internet | L20: Indisponibilidade de comunicação devido a problema no provedor de internet. | M20: Conexão c/ Internet | N20: Provedora de Internet | O20: Foi realizada inspeção visual no sistema, não sendo identificadas anomalias. Após a normalização do serviço de internet, a comunicação foi restabelecida e a usina voltou a operar normalmente. | P20: =_xlfn.CONCAT(B20,C20,D20,E20,F20) -> BC Bom SucessoB46082,968055555646082,968055555646083,3506944444 | Q20: =_xlfn.CONCAT(H20,I20,J20) -> LIGRFOINT
B21: BC Bom Sucesso | C21: A | D21: 46082.968 | E21: 46082.968 | F21: 46083.351 | G21: =+F21-E21 -> 0.38263889 | H21: LIG | I21: RFO | J21: INT | K21: =_xlfn.XLOOKUP(J21,REF!$D$2:$D$12,REF!$E$2:$E$12) -> Internet | L21: Indisponibilidade de comunicação devido a problema no provedor de internet. | M21: Conexão c/ Internet | N21: Provedora de Internet | O21: Foi realizada inspeção visual no sistema, não sendo identificadas anomalias. Após a normalização do serviço de internet, a comunicação foi restabelecida e a usina voltou a operar normalmente. | P21: =_xlfn.CONCAT(B21,C21,D21,E21,F21) -> BC Bom SucessoA46082,968055555646082,968055555646083,3506944444 | Q21: =_xlfn.CONCAT(H21,I21,J21) -> LIGRFOINT
B22: BC Bom Sucesso | C22: J | D22: 46082.968 | E22: 46082.968 | F22: 46083.351 | G22: =+F22-E22 -> 0.38263889 | H22: LIG | I22: RFO | J22: INT | K22: =_xlfn.XLOOKUP(J22,REF!$D$2:$D$12,REF!$E$2:$E$12) -> Internet | L22: Indisponibilidade de comunicação devido a problema no provedor de internet. | M22: Conexão c/ Internet | N22: Provedora de Internet | O22: Foi realizada inspeção visual no sistema, não sendo identificadas anomalias. Após a normalização do serviço de internet, a comunicação foi restabelecida e a usina voltou a operar normalmente. | P22: =_xlfn.CONCAT(B22,C22,D22,E22,F22) -> BC Bom SucessoJ46082,968055555646082,968055555646083,3506944444 | Q22: =_xlfn.CONCAT(H22,I22,J22) -> LIGRFOINT
... B27: BC Corumba2.2 | C27: U02.I05 | D27: 46083.455 | E27: 46083.455 | F27: 46083.5 | G27: =+F27-E27 -> 0.045138889 | H27: LIG | I27: RFO | J27: INT | K27: =_xlfn.XLOOKUP(J27,REF!$D$2:$D$12,REF!$E$2:$E$12) -> Internet | L27: Foi identificada instabilidade na comunicação do sistema. | M27: Falha Comunicação | N27: Auto-Restart | O27: A comunicação da UFV foi restabelecida automaticamente, retornando à operação normal. | P27: =_xlfn.CONCAT(B27,C27,D27,E27,F27) -> BC Corumba2.2U02.I0546083,454861111146083,454861111146083,5 | Q27: =_xlfn.CONCAT(H27,I27,J27) -> LIGRFOINT
B28: BC Formoso2.1 | C28: Inverter(MBUS-12) | D28: 46083.472 | E28: 46083.472 | F28: 46083.479 | G28: =+F28-E28 -> 0.0069444444 | H28: DAU | J28: RDE | K28: =_xlfn.XLOOKUP(J28,REF!$D$2:$D$12,REF!$E$2:$E$12) -> Rede | L28: Na Usina 2.1, o relé de proteção atuou nas funções 59B (sobretensão) e 27A (subtensão), ocasionando a atuação do sistema de proteção. | M28: Falha Rede | N28: Distribuidora | O28: Realizada inspeção visual no sistema, sem identificação de anomalias. Posteriormente, foi efetuado o reset dos relés de proteção e o rearme da usina, normalizando sua operação. | P28: =_xlfn.CONCAT(B28,C28,D28,E28,F28) -> BC Formoso2.1Inverter(MBUS-12)46083,472222222246083,472222222246083,4791666667 | Q28: =_xlfn.CONCAT(H28,I28,J28) -> DAURDE
B29: BC Formoso2.1 | C29: Inverter(MBUS-14) | D29: 46083.472 | E29: 46083.472 | F29: 46083.479 | G29: =+F29-E29 -> 0.0069444444 | H29: DAU | J29: RDE | K29: =_xlfn.XLOOKUP(J29,REF!$D$2:$D$12,REF!$E$2:$E$12) -> Rede | L29: Na Usina 2.1, o relé de proteção atuou nas funções 59B (sobretensão) e 27A (subtensão), ocasionando a atuação do sistema de proteção. | M29: Falha Rede | N29: Distribuidora | O29: Realizada inspeção visual no sistema, sem identificação de anomalias. Posteriormente, foi efetuado o reset dos relés de proteção e o rearme da usina, normalizando sua operação. | P29: =_xlfn.CONCAT(B29,C29,D29,E29,F29) -> BC Formoso2.1Inverter(MBUS-14)46083,472222222246083,472222222246083,4791666667 | Q29: =_xlfn.CONCAT(H29,I29,J29) -> DAURDE
B30: BC Formoso2.1 | C30: Inverter(MBUS-13) | D30: 46083.472 | E30: 46083.472 | F30: 46083.479 | G30: =+F30-E30 -> 0.0069444444 | H30: DAU | J30: RDE | K30: =_xlfn.XLOOKUP(J30,REF!$D$2:$D$12,REF!$E$2:$E$12) -> Rede | L30: Na Usina 2.1, o relé de proteção atuou nas funções 59B (sobretensão) e 27A (subtensão), ocasionando a atuação do sistema de proteção. | M30: Falha Rede | N30: Distribuidora | O30: Realizada inspeção visual no sistema, sem identificação de anomalias. Posteriormente, foi efetuado o reset dos relés de proteção e o rearme da usina, normalizando sua operação. | P30: =_xlfn.CONCAT(B30,C30,D30,E30,F30) -> BC Formoso2.1Inverter(MBUS-13)46083,472222222246083,472222222246083,4791666667 | Q30: =_xlfn.CONCAT(H30,I30,J30) -> DAURDE
B31: BC Formoso2.1 | C31: Inverter(MBUS-1) | D31: 46083.472 | E31: 46083.472 | F31: 46083.479 | G31: =+F31-E31 -> 0.0069444444 | H31: DAU | J31: RDE | K31: =_xlfn.XLOOKUP(J31,REF!$D$2:$D$12,REF!$E$2:$E$12) -> Rede | L31: Na Usina 2.1, o relé de proteção atuou nas funções 59B (sobretensão) e 27A (subtensão), ocasionando a atuação do sistema de proteção. | M31: Falha Rede | N31: Distribuidora | O31: Realizada inspeção visual no sistema, sem identificação de anomalias. Posteriormente, foi efetuado o reset dos relés de proteção e o rearme da usina, normalizando sua operação. | P31: =_xlfn.CONCAT(B31,C31,D31,E31,F31) -> BC Formoso2.1Inverter(MBUS-1)46083,472222222246083,472222222246083,4791666667 | Q31: =_xlfn.CONCAT(H31,I31,J31) -> DAURDE
B32: BC Formoso2.2 | C32: Inverter(MBUS-14) | D32: 46083.472 | E32: 46083.472 | F32: 46083.479 | G32: =+F32-E32 -> 0.0069444444 | H32: DAU | J32: RDE | K32: =_xlfn.XLOOKUP(J32,REF!$D$2:$D$12,REF!$E$2:$E$12) -> Rede | L32: Na Usina 2.2, o relé de proteção atuou nas funções 59A (sobretensão) e 27C (subtensão), ocasionando a atuação do sistema de proteção. | M32: Falha Rede | N32: Distribuidora | O32: Realizada inspeção visual no sistema, sem identificação de anomalias. Posteriormente, foi efetuado o reset dos relés de proteção e o rearme da usina, normalizando sua operação. | P32: =_xlfn.CONCAT(B32,C32,D32,E32,F32) -> BC Formoso2.2Inverter(MBUS-14)46083,472222222246083,472222222246083,4791666667 | Q32: =_xlfn.CONCAT(H32,I32,J32) -> DAURDE
B33: BC Formoso2.2 | C33: Inverter(MBUS-13) | D33: 46083.472 | E33: 46083.472 | F33: 46083.479 | G33: =+F33-E33 -> 0.0069444444 | H33: DAU | J33: RDE | K33: =_xlfn.XLOOKUP(J33,REF!$D$2:$D$12,REF!$E$2:$E$12) -> Rede | L33: Na Usina 2.2, o relé de proteção atuou nas funções 59A (sobretensão) e 27C (subtensão), ocasionando a atuação do sistema de proteção. | M33: Falha Rede | N33: Distribuidora | O33: Realizada inspeção visual no sistema, sem identificação de anomalias. Posteriormente, foi efetuado o reset dos relés de proteção e o rearme da usina, normalizando sua operação. | P33: =_xlfn.CONCAT(B33,C33,D33,E33,F33) -> BC Formoso2.2Inverter(MBUS-13)46083,472222222246083,472222222246083,4791666667 | Q33: =_xlfn.CONCAT(H33,I33,J33) -> DAURDE
B34: BC Formoso2.2 | C34: Inverter(MBUS-12) | D34: 46083.472 | E34: 46083.472 | F34: 46083.479 | G34: =+F34-E34 -> 0.0069444444 | H34: DAU | J34: RDE | K34: =_xlfn.XLOOKUP(J34,REF!$D$2:$D$12,REF!$E$2:$E$12) -> Rede | L34: Na Usina 2.2, o relé de proteção atuou nas funções 59A (sobretensão) e 27C (subtensão), ocasionando a atuação do sistema de proteção. | M34: Falha Rede | N34: Distribuidora | O34: Realizada inspeção visual no sistema, sem identificação de anomalias. Posteriormente, foi efetuado o reset dos relés de proteção e o rearme da usina, normalizando sua operação. | P34: =_xlfn.CONCAT(B34,C34,D34,E34,F34) -> BC Formoso2.2Inverter(MBUS-12)46083,472222222246083,472222222246083,4791666667 | Q34: =_xlfn.CONCAT(H34,I34,J34) -> DAURDE
B35: BC Formoso2.2 | C35: Inverter(MBUS-1) | D35: 46083.472 | E35: 46083.472 | F35: 46083.479 | G35: =+F35-E35 -> 0.0069444444 | H35: DAU | J35: RDE | K35: =_xlfn.XLOOKUP(J35,REF!$D$2:$D$12,REF!$E$2:$E$12) -> Rede | L35: Na Usina 2.2, o relé de proteção atuou nas funções 59A (sobretensão) e 27C (subtensão), ocasionando a atuação do sistema de proteção. | M35: Falha Rede | N35: Distribuidora | O35: Realizada inspeção visual no sistema, sem identificação de anomalias. Posteriormente, foi efetuado o reset dos relés de proteção e o rearme da usina, normalizando sua operação. | P35: =_xlfn.CONCAT(B35,C35,D35,E35,F35) -> BC Formoso2.2Inverter(MBUS-1)46083,472222222246083,472222222246083,4791666667 | Q35: =_xlfn.CONCAT(H35,I35,J35) -> DAURDE
B36: BC Formoso2.1 | C36: Inverter(MBUS-12) | D36: 46083.51 | E36: 46083.51 | F36: 46083.639 | G36: =+F36-E36 -> 0.12847222 | H36: DAU | J36: RDE | K36: =_xlfn.XLOOKUP(J36,REF!$D$2:$D$12,REF!$E$2:$E$12) -> Rede | L36: Na Usina 2.1, o relé de proteção atuou nas funções 59B (sobretensão) e 27A (subtensão), ocasionando a atuação do sistema de proteção. | M36: Falha Rede | N36: Distribuidora | O36: Realizada inspeção visual no sistema, sem identificação de anomalias. Posteriormente, foi efetuado o reset dos relés de proteção e o rearme da usina, normalizando sua operação. | P36: =_xlfn.CONCAT(B36,C36,D36,E36,F36) -> BC Formoso2.1Inverter(MBUS-12)46083,510416666746083,510416666746083,6388888889 | Q36: =_xlfn.CONCAT(H36,I36,J36) -> DAURDE
B37: BC Formoso2.1 | C37: Inverter(MBUS-14) | D37: 46083.51 | E37: 46083.51 | F37: 46083.639 | G37: =+F37-E37 -> 0.12847222 | H37: DAU | J37: RDE | K37: =_xlfn.XLOOKUP(J37,REF!$D$2:$D$12,REF!$E$2:$E$12) -> Rede | L37: Na Usina 2.1, o relé de proteção atuou nas funções 59B (sobretensão) e 27A (subtensão), ocasionando a atuação do sistema de proteção. | M37: Falha Rede | N37: Distribuidora | O37: Realizada inspeção visual no sistema, sem identificação de anomalias. Posteriormente, foi efetuado o reset dos relés de proteção e o rearme da usina, normalizando sua operação. | P37: =_xlfn.CONCAT(B37,C37,D37,E37,F37) -> BC Formoso2.1Inverter(MBUS-14)46083,510416666746083,510416666746083,6388888889 | Q37: =_xlfn.CONCAT(H37,I37,J37) -> DAURDE
B38: BC Formoso2.1 | C38: Inverter(MBUS-13) | D38: 46083.51 | E38: 46083.51 | F38: 46083.639 | G38: =+F38-E38 -> 0.12847222 | H38: DAU | J38: RDE | K38: =_xlfn.XLOOKUP(J38,REF!$D$2:$D$12,REF!$E$2:$E$12) -> Rede | L38: Na Usina 2.1, o relé de proteção atuou nas funções 59B (sobretensão) e 27A (subtensão), ocasionando a atuação do sistema de proteção. | M38: Falha Rede | N38: Distribuidora | O38: Realizada inspeção visual no sistema, sem identificação de anomalias. Posteriormente, foi efetuado o reset dos relés de proteção e o rearme da usina, normalizando sua operação. | P38: =_xlfn.CONCAT(B38,C38,D38,E38,F38) -> BC Formoso2.1Inverter(MBUS-13)46083,510416666746083,510416666746083,6388888889 | Q38: =_xlfn.CONCAT(H38,I38,J38) -> DAURDE
B39: BC Formoso2.1 | C39: Inverter(MBUS-1) | D39: 46083.51 | E39: 46083.51 | F39: 46083.639 | G39: =+F39-E39 -> 0.12847222 | H39: DAU | J39: RDE | K39: =_xlfn.XLOOKUP(J39,REF!$D$2:$D$12,REF!$E$2:$E$12) -> Rede | L39: Na Usina 2.1, o relé de proteção atuou nas funções 59B (sobretensão) e 27A (subtensão), ocasionando a atuação do sistema de proteção. | M39: Falha Rede | N39: Distribuidora | O39: Realizada inspeção visual no sistema, sem identificação de anomalias. Posteriormente, foi efetuado o reset dos relés de proteção e o rearme da usina, normalizando sua operação. | P39: =_xlfn.CONCAT(B39,C39,D39,E39,F39) -> BC Formoso2.1Inverter(MBUS-1)46083,510416666746083,510416666746083,6388888889 | Q39: =_xlfn.CONCAT(H39,I39,J39) -> DAURDE
... B67: BC Turvania1.3 | C67: Inverter(MBUS-13) | D67: 46084.288 | E67: 46084.288 | F67: 46084.354 | G67: =+F67-E67 -> 0.065972222 | H67: DAU | J67: STR | K67: =_xlfn.XLOOKUP(J67,REF!$D$2:$D$12,REF!$E$2:$E$12) -> String | L67: Durante a inspeção, foi identificado módulo danificado em curto-circuito. | M67: Falha String | N67: Prestador de Serviço O&M | O67: Foi realizada inspeção no inversor GR2449002585, sendo identificado um módulo em curto na string 3.1 da Usina 3. A string permanecerá desativada até que seja realizada a substituição do módulo danificado. Após a intervenção, o inversor voltou a operar com comunicação normal. | P67: =_xlfn.CONCAT(B67,C67,D67,E67,F67) -> BC Turvania1.3Inverter(MBUS-13)46084,288194444446084,288194444446084,3541666667 | Q67: =_xlfn.CONCAT(H67,I67,J67) -> DAUSTR
B68: BC Corumba2.2 | C68: U02.I01 | D68: 46084.292 | E68: 46084.292 | F68: 46084.333 | G68: =+F68-E68 -> 0.041666667 | H68: LIG | I68: RFO | J68: COM | K68: =_xlfn.XLOOKUP(J68,REF!$D$2:$D$12,REF!$E$2:$E$12) -> Comunicação | L68: Foi identificada uma interrupção na comunicação com o Smart Logger. | M68: Falha Comunicação | N68: Auto-Restart | O68: A comunicação da UFV foi restabelecida automaticamente, retornando à operação normal. | P68: =_xlfn.CONCAT(B68,C68,D68,E68,F68) -> BC Corumba2.2U02.I0146084,291666666746084,291666666746084,3333333333 | Q68: =_xlfn.CONCAT(H68,I68,J68) -> LIGRFOCOM
B69: BC Corumba2.2 | C69: U02.I02 | D69: 46084.292 | E69: 46084.292 | F69: 46084.333 | G69: =+F69-E69 -> 0.041666667 | H69: LIG | I69: RFO | J69: COM | K69: =_xlfn.XLOOKUP(J69,REF!$D$2:$D$12,REF!$E$2:$E$12) -> Comunicação | L69: Foi identificada uma interrupção na comunicação com o Smart Logger. | M69: Falha Comunicação | N69: Auto-Restart | O69: A comunicação da UFV foi restabelecida automaticamente, retornando à operação normal. | P69: =_xlfn.CONCAT(B69,C69,D69,E69,F69) -> BC Corumba2.2U02.I0246084,291666666746084,291666666746084,3333333333 | Q69: =_xlfn.CONCAT(H69,I69,J69) -> LIGRFOCOM
B70: BC Corumba2.2 | C70: U02.I03 | D70: 46084.292 | E70: 46084.292 | F70: 46084.333 | G70: =+F70-E70 -> 0.041666667 | H70: LIG | I70: RFO | J70: COM | K70: =_xlfn.XLOOKUP(J70,REF!$D$2:$D$12,REF!$E$2:$E$12) -> Comunicação | L70: Foi identificada uma interrupção na comunicação com o Smart Logger. | M70: Falha Comunicação | N70: Auto-Restart | O70: A comunicação da UFV foi restabelecida automaticamente, retornando à operação normal. | P70: =_xlfn.CONCAT(B70,C70,D70,E70,F70) -> BC Corumba2.2U02.I0346084,291666666746084,291666666746084,3333333333 | Q70: =_xlfn.CONCAT(H70,I70,J70) -> LIGRFOCOM
B71: BC Corumba2.2 | C71: U02.I04 | D71: 46084.292 | E71: 46084.292 | F71: 46084.333 | G71: =+F71-E71 -> 0.041666667 | H71: LIG | I71: RFO | J71: COM | K71: =_xlfn.XLOOKUP(J71,REF!$D$2:$D$12,REF!$E$2:$E$12) -> Comunicação | L71: Foi identificada uma interrupção na comunicação com o Smart Logger. | M71: Falha Comunicação | N71: Auto-Restart | O71: A comunicação da UFV foi restabelecida automaticamente, retornando à operação normal. | P71: =_xlfn.CONCAT(B71,C71,D71,E71,F71) -> BC Corumba2.2U02.I0446084,291666666746084,291666666746084,3333333333 | Q71: =_xlfn.CONCAT(H71,I71,J71) -> LIGRFOCOM
...

Sheet Fevereiro 2026
A1: UC | B1: UFV | C1: Tag | D1: Início Real do Evento | E1: Início | F1: Fim | G1: Duração | H1: Estado Operativo | I1: Condição Operativa | J1: Origem | K1: Equipamento | L1: Causa | M1: Causas Padrão | N1: Resolução | O1: Observação | P1: Concat - duplicata | Q1: Combinação
B2: BC Aracu5.2 | C2: Inverter(MBUS-1) | D2: 46027.385 | E2: 46054 | F2: 46081.999 | G2: 27.999988 | H2: DEM | J2: TRF | K2: Transformador | L2: Inversor 1 apresentou falha. Ao realizar a análise em campo, verificou-se curto circuito em uma das fases do trafo. | M2: Falha Inversor | N2: Prestador de Serviço O&M | O2: Após a retirada das strings que estavam em curto, foi realizado os testes e normalizado o inversor que segue operando sem anomalia. As strings serão reconectadas após realização de correção das strings. | P2: =_xlfn.CONCAT(B2,C2,D2,E2,F2) -> BC Aracu5.2Inverter(MBUS-1)46027,38541666674605446081,9993055556 | Q2: =_xlfn.CONCAT(H2,I2,J2) -> DEMTRF
B3: BC Aracu5.3 | C3: Inverter(MBUS-1) | D3: 46050.361 | E3: 46054 | F3: 46081.999 | G3: 27.999988 | H3: LIG | I3: RFO | J3: COM | K3: Comunicação | L3: Falha de comunicação | M3: Falha Rede | N3: Distribuidora | O3: Foi feito inspeção em todo complexo, checado nível de tensão e resetado relé e rearmado os disjuntores. | P3: =_xlfn.CONCAT(B3,C3,D3,E3,F3) -> BC Aracu5.3Inverter(MBUS-1)46050,36111111114605446081,9993055556 | Q3: =_xlfn.CONCAT(H3,I3,J3) -> LIGRFOCOM
B4: BC Turvania1.3 | C4: Inverter(MBUS-13) | D4: 46054.273 | E4: 46054.273 | F4: 46054.434 | G4: 0.16111111 | H4: DAU | J4: INV | K4: Inversor | L4: Inversor acusou falha de baixa impedância de isolamento, inicialmente, precedida das falhas de falha de energia de rede elétrica (indicando desligamento do inversor) e entrada DC é anormal (indicando anormalidade em algum componente CC). Durante inspeção em campo foi identificado que três strings do inversor estavam em curto. | M4: Falha Comunicação | N4: Auto-Restart | O4: Foi normalizado por si só. | P4: =_xlfn.CONCAT(B4,C4,D4,E4,F4) -> BC Turvania1.3Inverter(MBUS-13)46054,272916666746054,272916666746054,4340277778 | Q4: =_xlfn.CONCAT(H4,I4,J4) -> DAUINV
B5: BC Turvania1.3 | C5: Inverter(MBUS-13) | D5: 46054.434 | E5: 46054.434 | F5: 46081.999 | G5: 27.565961 | H5: LIG | I5: RFO | J5: STR | K5: String | L5: Inversor acusou falha de baixa impedância de isolamento, inicialmente, precedida das falhas de falha de energia de rede elétrica (indicando desligamento do inversor) e entrada DC é anormal (indicando anormalidade em algum componente CC). Durante inspeção em campo foi identificado que três strings do inversor estavam em curto. Strings ainda estão fora de operação. | M5: Falha Comunicação | N5: Auto-Restart | O5: Foi normalizado por si só. | P5: =_xlfn.CONCAT(B5,C5,D5,E5,F5) -> BC Turvania1.3Inverter(MBUS-13)46054,434027777846054,434027777846081,9993055556 | Q5: =_xlfn.CONCAT(H5,I5,J5) -> LIGRFOSTR
B6: BC Aracu5.1 | C6: Inverter(MBUS-1) | D6: 46054.36 | E6: 46054.36 | F6: 46054.387 | G6: 0.027083333 | H6: DAU | J6: RDE | K6: Rede | L6: Função 81 e 86 atuada no relé. | M6: Falha Comunicação | N6: Auto-Restart | O6: Foi normalizado por si só. | P6: =_xlfn.CONCAT(B6,C6,D6,E6,F6) -> BC Aracu5.1Inverter(MBUS-1)46054,360416666746054,360416666746054,3875 | Q6: =_xlfn.CONCAT(H6,I6,J6) -> DAURDE
B7: BC Aracu5.3 | C7: Inverter(MBUS-1) | D7: 46054.36 | E7: 46054.36 | F7: 46054.387 | G7: 0.027083333 | H7: DAU | J7: RDE | K7: Rede | L7: Função 81 e 86 atuada no relé. | M7: Falha Comunicação | N7: Auto-Restart | O7: Foi normalizado por si só. | P7: =_xlfn.CONCAT(B7,C7,D7,E7,F7) -> BC Aracu5.3Inverter(MBUS-1)46054,360416666746054,360416666746054,3875 | Q7: =_xlfn.CONCAT(H7,I7,J7) -> DAURDE
B8: BC Aracu5.4 | C8: Inverter(MBUS-1) | D8: 46054.36 | E8: 46054.36 | F8: 46054.387 | G8: 0.027083333 | H8: DAU | J8: RDE | K8: Rede | L8: Função 81 e 86 atuada no relé. | M8: Falha Comunicação | N8: Auto-Restart | O8: Foi normalizado por si só. | P8: =_xlfn.CONCAT(B8,C8,D8,E8,F8) -> BC Aracu5.4Inverter(MBUS-1)46054,360416666746054,360416666746054,3875 | Q8: =_xlfn.CONCAT(H8,I8,J8) -> DAURDE
B9: BC Aracu5.5 | C9: Inverter(MBUS-1) | D9: 46054.36 | E9: 46054.36 | F9: 46054.387 | G9: 0.027083333 | H9: DAU | J9: RDE | K9: Rede | L9: Função 81 e 86 atuada no relé. | M9: Falha Rede | N9: Distribuidora | O9: Foi feito inspeção em todo complexo, checado nível de tensão e resetado relé e rearmado os disjuntores. | P9: =_xlfn.CONCAT(B9,C9,D9,E9,F9) -> BC Aracu5.5Inverter(MBUS-1)46054,360416666746054,360416666746054,3875 | Q9: =_xlfn.CONCAT(H9,I9,J9) -> DAURDE
B10: BC Corumba2.2 | C10: U02.I01 | D10: 46054.384 | E10: 46054.384 | F10: 46054.417 | G10: 0.032638889 | H10: DAU | I10: RFO | J10: COM | K10: Comunicação | L10: Falha de comunicação no Smart Logger | M10: Falha Rede | N10: Distribuidora | O10: Inspecionado todo complexo, não foi identificado nenhuma anomalia, foi rearmado o disjuntor | P10: =_xlfn.CONCAT(B10,C10,D10,E10,F10) -> BC Corumba2.2U02.I0146054,384027777846054,384027777846054,4166666667 | Q10: =_xlfn.CONCAT(H10,I10,J10) -> DAURFOCOM
B11: BC Corumba2.2 | C11: U02.I02 | D11: 46054.384 | E11: 46054.384 | F11: 46054.417 | G11: 0.032638889 | H11: DAU | I11: RFO | J11: COM | K11: Comunicação | L11: Falha de comunicação no Smart Logger | M11: Falha Rede | N11: Distribuidora | O11: Inspecionado todo complexo, não foi identificado nenhuma anomalia, foi rearmado o disjuntor | P11: =_xlfn.CONCAT(B11,C11,D11,E11,F11) -> BC Corumba2.2U02.I0246054,384027777846054,384027777846054,4166666667 | Q11: =_xlfn.CONCAT(H11,I11,J11) -> DAURFOCOM
B12: BC Corumba2.2 | C12: U02.I03 | D12: 46054.384 | E12: 46054.384 | F12: 46054.417 | G12: 0.032638889 | H12: DAU | I12: RFO | J12: COM | K12: Comunicação | L12: Falha de comunicação no Smart Logger | M12: Falha Rede | N12: Distribuidora | O12: Inspecionado todo complexo, não foi identificado nenhuma anomalia, foi rearmado o disjuntor | P12: =_xlfn.CONCAT(B12,C12,D12,E12,F12) -> BC Corumba2.2U02.I0346054,384027777846054,384027777846054,4166666667 | Q12: =_xlfn.CONCAT(H12,I12,J12) -> DAURFOCOM
B13: BC Corumba2.2 | C13: U02.I04 | D13: 46054.384 | E13: 46054.384 | F13: 46054.417 | G13: 0.032638889 | H13: DAU | I13: RFO | J13: COM | K13: Comunicação | L13: Falha de comunicação no Smart Logger | M13: Falha Rede | N13: Distribuidora | O13: Inspecionado todo complexo, não foi identificado nenhuma anomalia, foi rearmado o disjuntor | P13: =_xlfn.CONCAT(B13,C13,D13,E13,F13) -> BC Corumba2.2U02.I0446054,384027777846054,384027777846054,4166666667 | Q13: =_xlfn.CONCAT(H13,I13,J13) -> DAURFOCOM
B14: BC Corumba2.2 | C14: U02.I05 | D14: 46054.384 | E14: 46054.384 | F14: 46054.417 | G14: 0.032638889 | H14: DAU | I14: RFO | J14: COM | K14: Comunicação | L14: Falha de comunicação no Smart Logger | M14: Falha Inversor | N14: Troca em Garantia | O14: Aguardando a garantia para efetuar a reposição do inversor | P14: =_xlfn.CONCAT(B14,C14,D14,E14,F14) -> BC Corumba2.2U02.I0546054,384027777846054,384027777846054,4166666667 | Q14: =_xlfn.CONCAT(H14,I14,J14) -> DAURFOCOM
B15: BC Vazante 1.1 | C15: Inverter12 | D15: 46054.415 | E15: 46054.415 | F15: 46054.443 | G15: 0.028472222 | H15: DAU | J15: RDE | K15: Rede | L15: Trip no disjuntor | M15: Manutenção | N15: Manutenção Corretiva | O15: Feita a manutenção do curto circuito. Inspecionado todo o complexo, tirado a oscilografia do relé de proteção. | P15: =_xlfn.CONCAT(B15,C15,D15,E15,F15) -> BC Vazante 1.1Inverter1246054,414583333346054,414583333346054,4430555556 | Q15: =_xlfn.CONCAT(H15,I15,J15) -> DAURDE
B16: ARAGUATINS 2.1 | C16: Inverter(MBUS-12) | D16: 46054.417 | E16: 46054.417 | F16: 46054.74 | G16: 0.32291667 | H16: DAU | J16: RDE | K16: Rede | L16: Queda de rede, sem função ativa no relé de proteção. Alarme 2032, indicando que a rede elétrica sofre uma interrupção ou o circuito CA está desconectado ou o disjuntor CA está desligado. | M16: Manutenção | N16: Manutenção Corretiva | O16: Feita a manutenção do curto circuito. Inspecionado todo o complexo, tirado a oscilografia do relé de proteção. | P16: =_xlfn.CONCAT(B16,C16,D16,E16,F16) -> ARAGUATINS 2.1Inverter(MBUS-12)46054,416666666746054,416666666746054,7395833333 | Q16: =_xlfn.CONCAT(H16,I16,J16) -> DAURDE
B17: ARAGUATINS 2.1 | C17: Inverter(MBUS-15) | D17: 46054.417 | E17: 46054.417 | F17: 46054.74 | G17: 0.32291667 | H17: DAU | J17: RDE | K17: Rede | L17: Queda de rede, sem função ativa no relé de proteção. Alarme 2032, indicando que a rede elétrica sofre uma interrupção ou o circuito CA está desconectado ou o disjuntor CA está desligado. | M17: Manutenção | N17: Manutenção Corretiva | O17: Feita a manutenção do curto circuito. Inspecionado todo o complexo, tirado a oscilografia do relé de proteção. | P17: =_xlfn.CONCAT(B17,C17,D17,E17,F17) -> ARAGUATINS 2.1Inverter(MBUS-15)46054,416666666746054,416666666746054,7395833333 | Q17: =_xlfn.CONCAT(H17,I17,J17) -> DAURDE
B18: ARAGUATINS 2.1 | C18: Inverter(MBUS-14) | D18: 46054.417 | E18: 46054.417 | F18: 46054.74 | G18: 0.32291667 | H18: DAU | J18: RDE | K18: Rede | L18: Queda de rede, sem função ativa no relé de proteção. Alarme 2032, indicando que a rede elétrica sofre uma interrupção ou o circuito CA está desconectado ou o disjuntor CA está desligado. | M18: Manutenção | N18: Manutenção Corretiva | O18: Feita a manutenção do curto circuito. Inspecionado todo o complexo, tirado a oscilografia do relé de proteção. | P18: =_xlfn.CONCAT(B18,C18,D18,E18,F18) -> ARAGUATINS 2.1Inverter(MBUS-14)46054,416666666746054,416666666746054,7395833333 | Q18: =_xlfn.CONCAT(H18,I18,J18) -> DAURDE
B19: ARAGUATINS 2.1 | C19: Inverter(MBUS-1) | D19: 46054.417 | E19: 46054.417 | F19: 46054.74 | G19: 0.32291667 | H19: DAU | J19: RDE | K19: Rede | L19: Queda de rede, sem função ativa no relé de proteção. Alarme 2032, indicando que a rede elétrica sofre uma interrupção ou o circuito CA está desconectado ou o disjuntor CA está desligado. | M19: Falha Comunicação | N19: Prestador de Serviço O&M | O19: Feito uma avaliação em todo o complexo, e identificado que o problema estava relacionado a comunicação. Após reiniciar o sistema, os inversores voltaram a comunicar no supervisorio | P19: =_xlfn.CONCAT(B19,C19,D19,E19,F19) -> ARAGUATINS 2.1Inverter(MBUS-1)46054,416666666746054,416666666746054,7395833333 | Q19: =_xlfn.CONCAT(H19,I19,J19) -> DAURDE
B20: BC Varjao1.3 | C20: 215KTL-H0(MBUS-14) | D20: 46055.299 | E20: 46055.299 | F20: 46081.999 | G20: 26.701377 | H20: LIG | I20: RFO | J20: INV | K20: Inversor | L20: Inversor com alarme acionado (2064), oscilando geração e não atinge potência nominal. Em tratativa sob o chamado 15218400. A Equipe de O&M está aguardando a emissão de notas de remessa pendentes para a huawei, com mais de 100 dias de atraso. Por conta dos atrasos, a huawei responde que "Em caso da falta de retorno das peças defeituosas em 30 dias o cliente estará sujeito a suspensão do envio de novas peças em garantias futuras. Caso o equipamento não seja devolvido dentro deste período, a Huawei reserva-se o direito de cobrar o preço de compra do produto / peças fornecido, degradar o SLA ou até mesmo parar com o envio de peças sobressalentes.". | M20: Falha Comunicação | N20: Prestador de Serviço O&M | O20: Feito uma avaliação em todo o complexo, e identificado que o problema estava relacionado a comunicação. Após reiniciar o sistema, os inversores voltaram a comunicar no supervisorio | P20: =_xlfn.CONCAT(B20,C20,D20,E20,F20) -> BC Varjao1.3215KTL-H0(MBUS-14)46055,298611111146055,298611111146081,9993055556 | Q20: =_xlfn.CONCAT(H20,I20,J20) -> LIGRFOINV
B21: ARAGUATINS 2.1 | C21: Inverter(MBUS-12) | D21: 46055.351 | E21: 46055.351 | F21: 46055.503 | G21: 0.15277778 | H21: DAU | J21: UFV | K21: UFV | L21: Desarme, sem nenhuma função ativa no relé de proteção. Identificado curto circuito na regua do borne do circuito de iluminação. | M21: Falha Comunicação | N21: Prestador de Serviço O&M | O21: Feito uma avaliação em todo o complexo, e identificado que o problema estava relacionado a comunicação. Após reiniciar o sistema, os inversores voltaram a comunicar no supervisorio | P21: =_xlfn.CONCAT(B21,C21,D21,E21,F21) -> ARAGUATINS 2.1Inverter(MBUS-12)46055,350694444446055,350694444446055,5034722222 | Q21: =_xlfn.CONCAT(H21,I21,J21) -> DAUUFV
B22: ARAGUATINS 2.1 | C22: Inverter(MBUS-15) | D22: 46055.351 | E22: 46055.351 | F22: 46055.503 | G22: 0.15277778 | H22: DAU | J22: UFV | K22: UFV | L22: Desarme, sem nenhuma função ativa no relé de proteção. Identificado curto circuito na regua do borne do circuito de iluminação. | M22: Falha Comunicação | N22: Prestador de Serviço O&M | O22: Feito uma avaliação em todo o complexo, e identificado que o problema estava relacionado a comunicação. Após reiniciar o sistema, os inversores voltaram a comunicar no supervisorio | P22: =_xlfn.CONCAT(B22,C22,D22,E22,F22) -> ARAGUATINS 2.1Inverter(MBUS-15)46055,350694444446055,350694444446055,5034722222 | Q22: =_xlfn.CONCAT(H22,I22,J22) -> DAUUFV
B23: ARAGUATINS 2.1 | C23: Inverter(MBUS-14) | D23: 46055.351 | E23: 46055.351 | F23: 46055.503 | G23: 0.15277778 | H23: DAU | J23: UFV | K23: UFV | L23: Desarme, sem nenhuma função ativa no relé de proteção. Identificado curto circuito na regua do borne do circuito de iluminação. | M23: Falha Comunicação | N23: Prestador de Serviço O&M | O23: Feito uma avaliação em todo o complexo, e identificado que o problema estava relacionado a comunicação. Após reiniciar o sistema, os inversores voltaram a comunicar no supervisorio | P23: =_xlfn.CONCAT(B23,C23,D23,E23,F23) -> ARAGUATINS 2.1Inverter(MBUS-14)46055,350694444446055,350694444446055,5034722222 | Q23: =_xlfn.CONCAT(H23,I23,J23) -> DAUUFV
B24: ARAGUATINS 2.1 | C24: Inverter(MBUS-1) | D24: 46055.351 | E24: 46055.351 | F24: 46055.503 | G24: 0.15277778 | H24: DAU | J24: UFV | K24: UFV | L24: Desarme, sem nenhuma função ativa no relé de proteção. Identificado curto circuito na regua do borne do circuito de iluminação. | M24: Falha Comunicação | N24: Prestador de Serviço O&M | O24: Feito uma avaliação em todo o complexo, e identificado que o problema estava relacionado a comunicação. Após reiniciar o sistema, os inversores voltaram a comunicar no supervisorio | P24: =_xlfn.CONCAT(B24,C24,D24,E24,F24) -> ARAGUATINS 2.1Inverter(MBUS-1)46055,350694444446055,350694444446055,5034722222 | Q24: =_xlfn.CONCAT(H24,I24,J24) -> DAUUFV
B25: BC Bom Sucesso | C25: SG60KTL | D25: 46055.382 | E25: 46055.382 | F25: 46055.447 | G25: 0.064583333 | H25: DAU | I25: RFO | J25: COM | K25: Comunicação | L25: Foi identificado que o supervisório e as câmeras estão funcionando parcialmente, câmeras ativas 2-6-10 | M25: Falha Comunicação | N25: Prestador de Serviço O&M | O25: Feito uma avaliação em todo o complexo, e identificado que o problema estava relacionado a comunicação. Após reiniciar o sistema, os inversores voltaram a comunicar no supervisorio | P25: =_xlfn.CONCAT(B25,C25,D25,E25,F25) -> BC Bom SucessoSG60KTL46055,381944444446055,381944444446055,4465277778 | Q25: =_xlfn.CONCAT(H25,I25,J25) -> DAURFOCOM
B26: BC Bom Sucesso | C26: I | D26: 46055.382 | E26: 46055.382 | F26: 46055.447 | G26: 0.064583333 | H26: DAU | I26: RFO | J26: COM | K26: Comunicação | L26: Foi identificado que o supervisório e as câmeras estão funcionando parcialmente, câmeras ativas 2-6-10 | M26: Falha Comunicação | N26: Prestador de Serviço O&M | O26: Feito uma avaliação em todo o complexo, e identificado que o problema estava relacionado a comunicação. Após reiniciar o sistema, os inversores voltaram a comunicar no supervisorio | P26: =_xlfn.CONCAT(B26,C26,D26,E26,F26) -> BC Bom SucessoI46055,381944444446055,381944444446055,4465277778 | Q26: =_xlfn.CONCAT(H26,I26,J26) -> DAURFOCOM
B27: BC Bom Sucesso | C27: G | D27: 46055.382 | E27: 46055.382 | F27: 46055.447 | G27: 0.064583333 | H27: DAU | I27: RFO | J27: COM | K27: Comunicação | L27: Foi identificado que o supervisório e as câmeras estão funcionando parcialmente, câmeras ativas 2-6-10 | M27: Falha Comunicação | N27: Prestador de Serviço O&M | O27: Feito uma avaliação em todo o complexo, e identificado que o problema estava relacionado a comunicação. Após reiniciar o sistema, os inversores voltaram a comunicar no supervisorio | P27: =_xlfn.CONCAT(B27,C27,D27,E27,F27) -> BC Bom SucessoG46055,381944444446055,381944444446055,4465277778 | Q27: =_xlfn.CONCAT(H27,I27,J27) -> DAURFOCOM
B28: BC Bom Sucesso | C28: K | D28: 46055.382 | E28: 46055.382 | F28: 46055.447 | G28: 0.064583333 | H28: DAU | I28: RFO | J28: COM | K28: Comunicação | L28: Foi identificado que o supervisório e as câmeras estão funcionando parcialmente, câmeras ativas 2-6-10 | M28: Falha Comunicação | N28: Prestador de Serviço O&M | O28: Feito uma avaliação em todo o complexo, e identificado que o problema estava relacionado a comunicação. Após reiniciar o sistema, os inversores voltaram a comunicar no supervisorio | P28: =_xlfn.CONCAT(B28,C28,D28,E28,F28) -> BC Bom SucessoK46055,381944444446055,381944444446055,4465277778 | Q28: =_xlfn.CONCAT(H28,I28,J28) -> DAURFOCOM
B29: BC Bom Sucesso | C29: H | D29: 46055.382 | E29: 46055.382 | F29: 46055.447 | G29: 0.064583333 | H29: DAU | I29: RFO | J29: COM | K29: Comunicação | L29: Foi identificado que o supervisório e as câmeras estão funcionando parcialmente, câmeras ativas 2-6-10 | M29: Falha Comunicação | N29: Prestador de Serviço O&M | O29: Feito uma avaliação em todo o complexo, e identificado que o problema estava relacionado a comunicação. Após reiniciar o sistema, os inversores voltaram a comunicar no supervisorio | P29: =_xlfn.CONCAT(B29,C29,D29,E29,F29) -> BC Bom SucessoH46055,381944444446055,381944444446055,4465277778 | Q29: =_xlfn.CONCAT(H29,I29,J29) -> DAURFOCOM
B30: BC Bom Sucesso | C30: F | D30: 46055.382 | E30: 46055.382 | F30: 46055.447 | G30: 0.064583333 | H30: DAU | I30: RFO | J30: COM | K30: Comunicação | L30: Foi identificado que o supervisório e as câmeras estão funcionando parcialmente, câmeras ativas 2-6-10 | M30: Falha Comunicação | N30: Prestador de Serviço O&M | O30: Feito uma avaliação em todo o complexo, e identificado que o problema estava relacionado a comunicação. Após reiniciar o sistema, os inversores voltaram a comunicar no supervisorio | P30: =_xlfn.CONCAT(B30,C30,D30,E30,F30) -> BC Bom SucessoF46055,381944444446055,381944444446055,4465277778 | Q30: =_xlfn.CONCAT(H30,I30,J30) -> DAURFOCOM
B31: BC Bom Sucesso | C31: D | D31: 46055.382 | E31: 46055.382 | F31: 46055.447 | G31: 0.064583333 | H31: DAU | I31: RFO | J31: COM | K31: Comunicação | L31: Foi identificado que o supervisório e as câmeras estão funcionando parcialmente, câmeras ativas 2-6-10 | M31: Falha Comunicação | N31: Prestador de Serviço O&M | O31: Foi feito uma inspeçao no CFTV no roteador e no suite, foi constatado problema de comunicação - queda de internet | P31: =_xlfn.CONCAT(B31,C31,D31,E31,F31) -> BC Bom SucessoD46055,381944444446055,381944444446055,4465277778 | Q31: =_xlfn.CONCAT(H31,I31,J31) -> DAURFOCOM
B32: BC Bom Sucesso | C32: E | D32: 46055.382 | E32: 46055.382 | F32: 46055.447 | G32: 0.064583333 | H32: DAU | I32: RFO | J32: COM | K32: Comunicação | L32: Foi identificado que o supervisório e as câmeras estão funcionando parcialmente, câmeras ativas 2-6-10 | M32: Falha Comunicação | N32: Prestador de Serviço O&M | O32: Foi feito uma inspeçao no CFTV no roteador e no suite, foi constatado problema de comunicação - queda de internet | P32: =_xlfn.CONCAT(B32,C32,D32,E32,F32) -> BC Bom SucessoE46055,381944444446055,381944444446055,4465277778 | Q32: =_xlfn.CONCAT(H32,I32,J32) -> DAURFOCOM
B33: BC Bom Sucesso | C33: C | D33: 46055.382 | E33: 46055.382 | F33: 46055.447 | G33: 0.064583333 | H33: DAU | I33: RFO | J33: COM | K33: Comunicação | L33: Foi identificado que o supervisório e as câmeras estão funcionando parcialmente, câmeras ativas 2-6-10 | M33: Falha Comunicação | N33: Prestador de Serviço O&M | O33: Foi feito uma inspeçao no CFTV no roteador e no suite, foi constatado problema de comunicação - queda de internet | P33: =_xlfn.CONCAT(B33,C33,D33,E33,F33) -> BC Bom SucessoC46055,381944444446055,381944444446055,4465277778 | Q33: =_xlfn.CONCAT(H33,I33,J33) -> DAURFOCOM
B34: BC Bom Sucesso | C34: B | D34: 46055.382 | E34: 46055.382 | F34: 46055.447 | G34: 0.064583333 | H34: DAU | I34: RFO | J34: COM | K34: Comunicação | L34: Foi identificado que o supervisório e as câmeras estão funcionando parcialmente, câmeras ativas 2-6-10 | M34: Falha Comunicação | N34: Prestador de Serviço O&M | O34: Foi feito uma inspeçao no CFTV no roteador e no suite, foi constatado problema de comunicação - queda de internet | P34: =_xlfn.CONCAT(B34,C34,D34,E34,F34) -> BC Bom SucessoB46055,381944444446055,381944444446055,4465277778 | Q34: =_xlfn.CONCAT(H34,I34,J34) -> DAURFOCOM
B35: BC Bom Sucesso | C35: A | D35: 46055.382 | E35: 46055.382 | F35: 46055.447 | G35: 0.064583333 | H35: DAU | I35: RFO | J35: COM | K35: Comunicação | L35: Foi identificado que o supervisório e as câmeras estão funcionando parcialmente, câmeras ativas 2-6-10 | M35: Falha Comunicação | N35: Prestador de Serviço O&M | O35: Foi feito uma inspeçao no CFTV no roteador e no suite, foi constatado problema de comunicação - queda de internet | P35: =_xlfn.CONCAT(B35,C35,D35,E35,F35) -> BC Bom SucessoA46055,381944444446055,381944444446055,4465277778 | Q35: =_xlfn.CONCAT(H35,I35,J35) -> DAURFOCOM
B36: BC Bom Sucesso | C36: J | D36: 46055.382 | E36: 46055.382 | F36: 46055.447 | G36: 0.064583333 | H36: DAU | I36: RFO | J36: COM | K36: Comunicação | L36: Foi identificado que o supervisório e as câmeras estão funcionando parcialmente, câmeras ativas 2-6-10 | M36: Manutenção | N36: Manutenção Preventiva | O36: Foi realizado limpeza nos coolers e nos inversores | P36: =_xlfn.CONCAT(B36,C36,D36,E36,F36) -> BC Bom SucessoJ46055,381944444446055,381944444446055,4465277778 | Q36: =_xlfn.CONCAT(H36,I36,J36) -> DAURFOCOM
... B40: BC Aracu5.5 | C40: Inverter(MBUS-1) | D40: 46055.389 | E40: 46055.389 | F40: 46055.457 | G40: 0.068055556 | H40: DAU | I40: RFO | J40: INT | K40: Internet | L40: Foi identificado no supervisório que todos as câmeras e inversores estão Off-line | M40: Falha Rede | N40: Distribuidora | O40: Normalizou sozinho com o retorno da energia | P40: =_xlfn.CONCAT(B40,C40,D40,E40,F40) -> BC Aracu5.5Inverter(MBUS-1)46055,388888888946055,388888888946055,4569444444 | Q40: =_xlfn.CONCAT(H40,I40,J40) -> DAURFOINT
B41: BC Aracu4 | C41: SG75CX(COM1-018)_001_018 | D41: 46055.667 | E41: 46055.667 | F41: 46055.715 | G41: 0.047916667 | H41: DPR | J41: INV | K41: Inversor | L41: Desligamento programado para manutenção preventiva nos inversores. | M41: Falha Rede | N41: Distribuidora | O41: Normalizou sozinho com o retorno da energia | P41: =_xlfn.CONCAT(B41,C41,D41,E41,F41) -> BC Aracu4SG75CX(COM1-018)_001_01846055,666666666746055,666666666746055,7145833333 | Q41: =_xlfn.CONCAT(H41,I41,J41) -> DPRINV
B42: BC Aracu4 | C42: SG75CX(COM1-019)_001_019 | D42: 46055.667 | E42: 46055.667 | F42: 46055.715 | G42: 0.047916667 | H42: DPR | J42: INV | K42: Inversor | L42: Desligamento programado para manutenção preventiva nos inversores. | M42: Falha Rede | N42: Distribuidora | O42: Normalizou sozinho com o retorno da energia | P42: =_xlfn.CONCAT(B42,C42,D42,E42,F42) -> BC Aracu4SG75CX(COM1-019)_001_01946055,666666666746055,666666666746055,7145833333 | Q42: =_xlfn.CONCAT(H42,I42,J42) -> DPRINV
B43: BC Aracu4 | C43: SG75CX(COM1-020)_001_020 | D43: 46055.667 | E43: 46055.667 | F43: 46055.715 | G43: 0.047916667 | H43: DPR | J43: INV | K43: Inversor | L43: Desligamento programado para manutenção preventiva nos inversores. | M43: Falha Rede | N43: Distribuidora | O43: Normalizou sozinho com o retorno da energia | P43: =_xlfn.CONCAT(B43,C43,D43,E43,F43) -> BC Aracu4SG75CX(COM1-020)_001_02046055,666666666746055,666666666746055,7145833333 | Q43: =_xlfn.CONCAT(H43,I43,J43) -> DPRINV
...

Sheet  Janeiro 2026
A1: UC | B1: UFV | C1: Tag | D1: Início Real do Evento | E1: Início | F1: Fim | G1: Duração | H1: Estado Operativo | I1: Condição Operativa | J1: Origem | K1: Equipamento | L1: Causa | M1: Causas Padrão | N1: Resolução | O1: Observação | P1: Concat - duplicata | Q1: Combinação
B2: BC Caiaponia2.1 | C2: 215KTL-H3(MBUS-12) | D2: 46023.088 | E2: 46023.088 | F2: 46023.901 | G2: =F2-E2 -> 0.81388889 | H2: DAU | J2: RDE | K2: =_xlfn.XLOOKUP(J2,REF!$D$2:$D$12,REF!$E$2:$E$12) -> Rede | L2: Queda de rede da concessionária. | M2: Falha Rede | N2: Distribuidora | O2: Foi feito inspeção em todo complexo, checado nível de tensão e resetado relé e rearmado os disjuntores. | P2: =_xlfn.CONCAT(B2,C2,D2,E2,F2) -> BC Caiaponia2.1215KTL-H3(MBUS-12)46023,087546023,087546023,9013888889 | Q2: =_xlfn.CONCAT(H2,I2,J2) -> DAURDE
B3: BC Caiaponia2.1 | C3: 215KTL-H3(MBUS-13) | D3: 46023.088 | E3: 46023.088 | F3: 46023.901 | G3: =F3-E3 -> 0.81388889 | H3: DAU | J3: RDE | K3: =_xlfn.XLOOKUP(J3,REF!$D$2:$D$12,REF!$E$2:$E$12) -> Rede | L3: Queda de rede da concessionária. | M3: Falha Rede | N3: Distribuidora | O3: Foi feito inspeção em todo complexo, checado nível de tensão e resetado relé e rearmado os disjuntores. | P3: =_xlfn.CONCAT(B3,C3,D3,E3,F3) -> BC Caiaponia2.1215KTL-H3(MBUS-13)46023,087546023,087546023,9013888889 | Q3: =_xlfn.CONCAT(H3,I3,J3) -> DAURDE
